Traceback (most recent call last):
  File "/Users/Karen/opt/anaconda3/lib/python3.8/site-packages/jupyter_cache/executors/utils.py", line 51, in single_nb_execution
    executenb(
  File "/Users/Karen/opt/anaconda3/lib/python3.8/site-packages/nbclient/client.py", line 1082, in execute
    return NotebookClient(nb=nb, resources=resources, km=km, **kwargs).execute()
  File "/Users/Karen/opt/anaconda3/lib/python3.8/site-packages/nbclient/util.py", line 74, in wrapped
    return just_run(coro(*args, **kwargs))
  File "/Users/Karen/opt/anaconda3/lib/python3.8/site-packages/nbclient/util.py", line 53, in just_run
    return loop.run_until_complete(coro)
  File "/Users/Karen/opt/anaconda3/lib/python3.8/asyncio/base_events.py", line 616, in run_until_complete
    return future.result()
  File "/Users/Karen/opt/anaconda3/lib/python3.8/site-packages/nbclient/client.py", line 535, in async_execute
    await self.async_execute_cell(
  File "/Users/Karen/opt/anaconda3/lib/python3.8/site-packages/nbclient/client.py", line 827, in async_execute_cell
    self._check_raise_for_error(cell, exec_reply)
  File "/Users/Karen/opt/anaconda3/lib/python3.8/site-packages/nbclient/client.py", line 735, in _check_raise_for_error
    raise CellExecutionError.from_cell_and_msg(cell, exec_reply['content'])
nbclient.exceptions.CellExecutionError: An error occurred while executing the following cell:
------------------
display_quiz(fileJson)
------------------

[0;31m---------------------------------------------------------------------------[0m
[0;31mAttributeError[0m                            Traceback (most recent call last)
[0;32m<ipython-input-2-dc64fa9fee92>[0m in [0;36m<module>[0;34m[0m
[0;32m----> 1[0;31m [0mdisplay_quiz[0m[0;34m([0m[0mfileJson[0m[0;34m)[0m[0;34m[0m[0;34m[0m[0m
[0m
[0;32m~/opt/anaconda3/lib/python3.8/site-packages/jupyterquiz/dynamic.py[0m in [0;36mdisplay_quiz[0;34m(ref, num, shuffle_questions, shuffle_answers, preserve_responses, border_radius, question_alignment, max_width, colors)[0m
[1;32m    124[0m     [0mstyles[0m[0;34m+=[0m [0;34m"}\n\n"[0m[0;34m[0m[0;34m[0m[0m
[1;32m    125[0m     [0;31m#print(styles)[0m[0;34m[0m[0;34m[0m[0;34m[0m[0m
[0;32m--> 126[0;31m     [0mf[0m [0;34m=[0m [0mimportlib[0m[0;34m.[0m[0mresources[0m[0;34m.[0m[0mfiles[0m[0;34m([0m[0mpackage[0m[0;34m)[0m[0;34m.[0m[0mjoinpath[0m[0;34m([0m[0;34m'styles.css'[0m[0;34m)[0m[0;34m[0m[0;34m[0m[0m
[0m[1;32m    127[0m     [0mcss[0m [0;34m=[0m [0mf[0m[0;34m.[0m[0mread_bytes[0m[0;34m([0m[0;34m)[0m[0;34m[0m[0;34m[0m[0m
[1;32m    128[0m     [0mstyles[0m [0;34m+=[0m [0mcss[0m[0;34m.[0m[0mdecode[0m[0;34m([0m[0;34m"utf-8"[0m[0;34m)[0m[0;34m[0m[0;34m[0m[0m

[0;31mAttributeError[0m: module 'importlib.resources' has no attribute 'files'
AttributeError: module 'importlib.resources' has no attribute 'files'

